Workbook

Sheet Sheet1
B2: Comparable Company Analysis - JSW Steel (Method-1)
B4: amount in crores
D5: Market Data of Peers | M5: Multiples
B7: Company | D7: Share price | E7: Share Outstanding | F7: Enterprise Value | G7: Sales | H7: Debt | I7: Share Capital | J7: Net profit | K7: EBITDA | M7: EV/EBITDA | N7: EV/Sales | O7: Price/BV
B9: JSW Steel | D9: 1301.1 | E9: 244.6945 | F9: 376693.01 | G9: 185470 | H9: 99310 | I9: 100053 | J9: 25508 | K9: =Sheet1!F9/Sheet1!M9 -> 30600.569 | M9: 12.31 | N9: =F9/G9 -> 2.0310185 | O9: 3.18
B10: Tata Steel | D10: 210.57 | E10: 1248.8832 | F10: 345301.48 | G10: 232139.94 | H10: 92381.68 | I10: 102167.65 | J10: 10885.82 | K10: =Sheet1!F10/Sheet1!M10 -> 36119.402 | M10: 9.56 | N10: =F10/G10 -> 1.4874712 | O10: 2.57
B11: Jindal Steel | D11: 1197.2 | E11: 102.00038 | F11: 140582.81 | G11: 53224.92 | H11: 22609.55 | I11: 50898.91 | J11: 3360.87 | K11: =Sheet1!F11/Sheet1!M11 -> 9970.4121 | M11: 14.1 | N11: =F11/G11 -> 2.6412968 | O11: 2.4
B12: S A I L | D12: 197.31 | E12: 413.19441 | F12: 112722.59 | G12: 110810.84 | H12: 31927.71 | I12: 60355.88 | J12: 3372.8 | K12: =Sheet1!F12/Sheet1!M12 -> 13324.183 | M12: 8.46 | N12: =F12/G12 -> 1.0172524 | O12: 1.35
B13: Jindal Stain. | D13: 696.75 | E13: 82.399641 | F13: 61938.25 | G13: 42954.66 | H13: 7460.33 | I13: 19791.28 | J13: 3184.57 | K13: =Sheet1!F13/Sheet1!M13 -> 5927.1053 | M13: 10.45 | N13: =F13/G13 -> 1.4419448 | O13: 2.9
B14: Sarda Energy | D14: 532.2 | E14: 35.268602 | F14: 20537.38 | G14: 5690.45 | H14: 2631.92 | I14: 7370 | J14: 1109.44 | K14: =Sheet1!F14/Sheet1!M14 -> 2025.3826 | M14: 10.14 | N14: =F14/G14 -> 3.6090959 | O14: 2.54
B15: NMDC Steel | D15: 50.72 | E15: 293.06073 | F15: 18677.24 | G15: 13641.81 | H15: 4613.18 | I15: 13173.2 | J15: 58.72 | K15: =Sheet1!F15/Sheet1!M15 -> 1604.5739 | M15: 11.64 | N15: =F15/G15 -> 1.3691174 | O15: 1.13
B16: Jai Balaji Industry | D16: 70.37 | E16: 90.467671 | F16: 6722.5 | G16: 5784.27 | H16: 416.63 | I16: 2257.56 | J16: 129.95 | K16: =Sheet1!F16/Sheet1!M16 -> 385.907 | M16: 17.42 | N16: =F16/G16 -> 1.1622037 | O16: 2.84
B17: Prakash Industry | D17: 146.39 | E17: 17.871439 | F17: 2936.14 | G17: 3478.66 | H17: 515.4 | I17: 3588.37 | J17: 333.14 | K17: =Sheet1!F17/Sheet1!M17 -> 542.72458 | M17: 5.41 | N17: =F17/G17 -> 0.8440434 | O17: 0.73
B18: Mukand | D18: 139.67 | E18: 14.453712 | F18: 3695.6 | G18: 4889.83 | H18: 1696.71 | I18: 1522.33 | J18: 604.1 | K18: =Sheet1!F18/Sheet1!M18 -> 724.62745 | M18: 5.1 | N18: =F18/G18 -> 0.7557727 | O18: 1.33
B20: Average | M20: =AVERAGE(M9:M18) -> 10.459 | N20: =AVERAGE(N9:N18) -> 1.6359217 | O20: =AVERAGE(O9:O18) -> 2.097
B21: High | M21: =MAX(M9:M18) -> 17.42 | N21: =MAX(N9:N18) -> 3.6090959 | O21: =MAX(O9:O18) -> 3.18
B22: 75th Percnetile | M22: =QUARTILE(M9:M18,3) -> 12.1425 | N22: =QUARTILE(N9:N18,3) -> 1.8951317 | O22: =QUARTILE(O9:O18,3) -> 2.7725
B23: Median | M23: =QUARTILE(M9:M18,2) -> 10.295 | N23: =QUARTILE(N9:N18,2) -> 1.4055311 | O23: =QUARTILE(O9:O18,2) -> 2.47
B24: 25th Percentile | M24: =QUARTILE(M9:M18,1) -> 8.735 | N24: =QUARTILE(N9:N18,1) -> 1.0534902 | O24: =QUARTILE(O9:O18,1) -> 1.335
B25: Low | M25: =MIN(M9:M18) -> 5.1 | N25: =MIN(N9:N18) -> 0.7557727 | O25: =MIN(O9:O18) -> 0.73
B29: Relative Valuation of JSw steel
B31: Particulars | M31: =M7 -> EV/EBITDA | N31: =N7 -> EV/Sales | O31: =O7 -> Price/BV
B33: Implied Enterprise Value | M33: =K9*M9 -> 376693.01 | N33: =N23*G9 -> 260683.86
B34: Net Debt | M34: =H9 -> 99310 | N34: =M34 -> 99310
B35: Implied Market Value Of Equity | M35: =M33-M34 -> 277383.01 | N35: =N33-N34 -> 161373.86 | O35: =O23*I9 -> 247130.91
B36: Share Outstanding | M36: =E9 -> 244.6945 | N36: =M36 -> 244.6945 | O36: =N36 -> 244.6945
B37: Implied Value Of Share | M37: =M35/M36 -> 1133.5891 | N37: =N35/N36 -> 659.49117 | O37: =O35/O36 -> 1009.957
M39: =IF($D$9>M37,"OverValued","UnderValued") -> OverValued | N39: =IF($D$9>N37,"OverValued","UnderValued") -> OverValued | O39: =IF($D$9>O37,"OverValued","UnderValued") -> OverValued
B42: Key insghts
B44: JSW ltd multiples are higher than its peers average multiples implies that JSW ltd is on an average higher than its peers
B45: Based on all three multipels (EV/Sales, EV/EBITDA, P/BV) we can say that JSW ltd is overvalued
B46: Average implied value of JSW ltd is 931 less than its current market price 1304

Sheet SSEI
B2: Comparable Company Analysis - JSW Steel (Method-2)
B4: amount in crores
D5: Market Data of Peers | N5: Multiples
B7: Company | D7: Share price | E7: Share Outstanding | G7: Enterprise Value | H7: Sales | I7: Debt | J7: Share Capital | K7: Net profit | L7: EBITDA | N7: EV/EBITDA | O7: EV/Sales | P7: Price/BV
B9: JSW Steel | D9: 1301.1 | E9: 244.6945 | G9: 376693.01 | H9: 185470 | I9: 99310 | J9: 100053 | K9: 25508 | L9: =SSEI!G9/SSEI!N9 -> 30600.569 | N9: 12.31 | O9: =G9/H9 -> 2.0310185 | P9: 3.18
B10: Tata Steel | D10: 210.57 | E10: 1248.8832 | G10: 345301.48 | H10: 232139.94 | I10: 92381.68 | J10: 102167.65 | K10: 10885.82 | L10: =SSEI!G10/SSEI!N10 -> 36119.402 | N10: 9.56 | O10: =G10/H10 -> 1.4874712 | P10: 2.57
B11: Jindal Steel | D11: 1197.2 | E11: 102.00038 | G11: 140582.81 | H11: 53224.92 | I11: 22609.55 | J11: 50898.91 | K11: 3360.87 | L11: =SSEI!G11/SSEI!N11 -> 9970.4121 | N11: 14.1 | O11: =G11/H11 -> 2.6412968 | P11: 2.4
B12: S A I L | D12: 197.31 | E12: 413.19441 | G12: 112722.59 | H12: 110810.84 | I12: 31927.71 | J12: 60355.88 | K12: 3372.8 | L12: =SSEI!G12/SSEI!N12 -> 13324.183 | N12: 8.46 | O12: =G12/H12 -> 1.0172524 | P12: 1.35
B13: Jindal Stain. | D13: 696.75 | E13: 82.399641 | G13: 61938.25 | H13: 42954.66 | I13: 7460.33 | J13: 19791.28 | K13: 3184.57 | L13: =SSEI!G13/SSEI!N13 -> 5927.1053 | N13: 10.45 | O13: =G13/H13 -> 1.4419448 | P13: 2.9
B14: Sarda Energy | D14: 532.2 | E14: 35.268602 | G14: 20537.38 | H14: 5690.45 | I14: 2631.92 | J14: 7370 | K14: 1109.44 | L14: =SSEI!G14/SSEI!N14 -> 2025.3826 | N14: 10.14 | O14: =G14/H14 -> 3.6090959 | P14: 2.54
B15: NMDC Steel | D15: 50.72 | E15: 293.06073 | G15: 18677.24 | H15: 13641.81 | I15: 4613.18 | J15: 13173.2 | K15: 58.72 | L15: =SSEI!G15/SSEI!N15 -> 1604.5739 | N15: 11.64 | O15: =G15/H15 -> 1.3691174 | P15: 1.13
B16: Jai Balaji Industry | D16: 70.37 | E16: 90.467671 | G16: 6722.5 | H16: 5784.27 | I16: 416.63 | J16: 2257.56 | K16: 129.95 | L16: =SSEI!G16/SSEI!N16 -> 385.907 | N16: 17.42 | O16: =G16/H16 -> 1.1622037 | P16: 2.84
B17: Prakash Industry | D17: 146.39 | E17: 17.871439 | G17: 2936.14 | H17: 3478.66 | I17: 515.4 | J17: 3588.37 | K17: 333.14 | L17: =SSEI!G17/SSEI!N17 -> 542.72458 | N17: 5.41 | O17: =G17/H17 -> 0.8440434 | P17: 0.73
B18: Mukand | D18: 139.67 | E18: 14.453712 | G18: 3695.6 | H18: 4889.83 | I18: 1696.71 | J18: 1522.33 | K18: 604.1 | L18: =SSEI!G18/SSEI!N18 -> 724.62745 | N18: 5.1 | O18: =G18/H18 -> 0.7557727 | P18: 1.33
B20: Average | N20: =AVERAGE(N9:N18) -> 10.459 | O20: =AVERAGE(O9:O18) -> 1.6359217 | P20: =AVERAGE(P9:P18) -> 2.097
B21: High | N21: =MAX(N9:N18) -> 17.42 | O21: =MAX(O9:O18) -> 3.6090959 | P21: =MAX(P9:P18) -> 3.18
B22: 75th Percnetile | N22: =QUARTILE(N9:N18,3) -> 12.1425 | O22: =QUARTILE(O9:O18,3) -> 1.8951317 | P22: =QUARTILE(P9:P18,3) -> 2.7725
B23: Median | N23: =QUARTILE(N9:N18,2) -> 10.295 | O23: =QUARTILE(O9:O18,2) -> 1.4055311 | P23: =QUARTILE(P9:P18,2) -> 2.47
B24: 25th Percentile | N24: =QUARTILE(N9:N18,1) -> 8.735 | O24: =QUARTILE(O9:O18,1) -> 1.0534902 | P24: =QUARTILE(P9:P18,1) -> 1.335
B25: Low | N25: =MIN(N9:N18) -> 5.1 | O25: =MIN(O9:O18) -> 0.7557727 | P25: =MIN(P9:P18) -> 0.73
D28: Assigned weight to peers | G28: Weghted Average of multipules
B30: Company | D30: Market Cap | E30: Weights | G30: =N7 -> EV/EBITDA | H30: =O7 -> EV/Sales | I30: =P7 -> Price/BV
B32: JSW Steel | D32: =D9*E9 -> 318372.01 | E32: =D32/$D$42 -> 0.35891558 | G32: =N9*E32 -> 4.4182508 | H32: =O9*E32 -> 0.72896421 | I32: =P9*E32 -> 1.1413516
B33: Tata Steel | D33: =D10*E10 -> 262977.33 | E33: =D33/$D$42 -> 0.29646658 | G33: =N10*E33 -> 2.8342205 | H33: =O10*E33 -> 0.44098551 | I33: =P10*E33 -> 0.76191912
B34: Jindal Steel | D34: =D11*E11 -> 122114.86 | E34: =D34/$D$42 -> 0.13766577 | G34: =N11*E34 -> 1.9410873 | H34: =O11*E34 -> 0.36361614 | I34: =P11*E34 -> 0.33039784
B35: S A I L | D35: =D12*E12 -> 81527.39 | E35: =D35/$D$42 -> 0.091909621 | G35: =N12*E35 -> 0.7775554 | H35: =O12*E35 -> 0.09349528 | I35: =P12*E35 -> 0.12407799
B36: Jindal Stain. | D36: =D13*E13 -> 57411.95 | E36: =D36/$D$42 -> 0.064723163 | G36: =N13*E36 -> 0.67635706 | H36: =O13*E36 -> 0.093327231 | I36: =P13*E36 -> 0.18769717
B37: Sarda Energy | D37: =D14*E14 -> 18769.95 | E37: =D37/$D$42 -> 0.021160238 | G37: =N14*E37 -> 0.21456482 | H37: =O14*E37 -> 0.07636933 | I37: =P14*E37 -> 0.053747005
B38: NMDC Steel | D38: =D15*E15 -> 14864.04 | E38: =D38/$D$42 -> 0.016756924 | G38: =N15*E38 -> 0.1950506 | H38: =O15*E38 -> 0.022942197 | I38: =P15*E38 -> 0.018935324
B39: Jai Balaji Industry | D39: =D16*E16 -> 6366.21 | E39: =D39/$D$42 -> 0.0071769248 | G39: =N16*E39 -> 0.12502203 | H39: =O16*E39 -> 0.0083410486 | I39: =P16*E39 -> 0.020382467
B40: Prakash Industry | D40: =D17*E17 -> 2616.2 | E40: =D40/$D$42 -> 0.002949364 | G40: =N17*E40 -> 0.015956059 | H40: =O17*E40 -> 0.0024893912 | I40: =P17*E40 -> 0.0021530357
B41: Mukand | D41: =D18*E18 -> 2018.75 | E41: =D41/$D$42 -> 0.0022758308 | G41: =N18*E41 -> 0.011606737 | H41: =O18*E41 -> 0.0017200108 | I41: =P18*E41 -> 0.003026855
D42: =SUM(D32:D41) -> 887038.69 | E42: =SUM(E32:E41) -> 1 | G42: =SUM(G32:G41) -> 11.209671 | H42: =SUM(H32:H41) -> 1.8322504 | I42: =SUM(I32:I41) -> 2.6436884
B46: Qualitative Driver Scorecard (JSW steel V/S Peers)
B48: Key Valuation Driver | E48: Score | G48: Rational
B49: 1 Brand Equity | E49: 2 | G49: One of the largest steel producer in India
B50: 2 Operating Efficiency | E50: 1 | G50: competitive cost structure
B51: 3 Growht Potential | E51: 2 | G51: Signification capacity expansion plan
B52: 4 Financial Risk/Defensiveness | E52: -1 | G52: High debt compare to peers
B53: 5 Product Range | E53: 1 | G53: presence across flat, long and coated steel
...

Sheet Data Sheet
A2: S.No. | B2: Name | C2: CMP Rs. | D2: Mar Cap Rs.Cr. | E2: EV Rs.Cr. | F2: Sales Rs.Cr. | G2: Eq Cap Rs.Cr. | H2: Reserves Rs.Cr. | I2: ebitda
A3: 1 | B3: JSW Steel | C3: 1301.1 | D3: 318372.01 | E3: 376693.01 | F3: 185470 | G3: 305 | H3: 99748 | I3: 30600.569
A4: 2 | B4: Tata Steel | C4: 210.57 | D4: 262977.33 | E4: 345301.48 | F4: 232139.94 | G4: 1247.44 | H4: 100920.21 | I4: 36119.402
A5: 3 | B5: Jindal Steel | C5: 1197.2 | D5: 122114.86 | E5: 140582.81 | F5: 53224.92 | G5: 101.75 | H5: 50797.16 | I5: 9970.4121
A6: 4 | B6: S A I L | C6: 197.31 | D6: 81527.39 | E6: 112722.59 | F6: 110810.84 | G6: 4130.53 | H6: 56225.35 | I6: 13324.183
A7: 5 | B7: Jindal Stain. | C7: 696.75 | D7: 57411.95 | E7: 61938.25 | F7: 42954.66 | G7: 164.79 | H7: 19626.49 | I7: 5927.1053
A8: 6 | B8: Sarda Energy | C8: 532.2 | D8: 18769.95 | E8: 20537.38 | F8: 5690.45 | G8: 35.24 | H8: 7334.76 | I8: 2025.3826
A9: 7 | B9: NMDC Steel | C9: 50.72 | D9: 14864.04 | E9: 18677.24 | F9: 13641.81 | G9: 2930.61 | H9: 10242.59 | I9: 1604.5739
A10: 8 | B10: Jai Balaji Inds. | C10: 70.37 | D10: 6366.21 | E10: 6722.5 | F10: 5784.27 | G10: 182.45 | H10: 2075.11 | I10: 385.907
A11: 9 | B11: Prakash Industri | C11: 146.39 | D11: 2616.2 | E11: 2936.14 | F11: 3478.66 | G11: 179.08 | H11: 3409.29 | I11: 542.72458
A12: 10 | B12: Mukand | C12: 139.67 | D12: 2018.75 | E12: 3695.6 | F12: 4889.83 | G12: 144.51 | H12: 1377.82 | I12: 724.62745
